Workbook

Sheet Data_Motor
A1: Riepilogo motore e ipotesi di progetto – Feetech ST-3215-C018
A3: Fonte principale | B3: Datasheet caricato: Feetech ST-3215-C018 (2023-07-20)
A4: Modello | B4: ST-3215-C018
A5: Tipo | B5: Smart serial bus servo TTL con encoder magnetico 12 bit
A6: Applicazione | B6: Cane robot quadrupede 12 DOF
A8: Specifiche elettriche ufficiali (@12V)
A9: Parametro | B9: Valore | C9: Origine | D9: Note
A10: Tensione nominale | B10: 12 V | C10: Datasheet Feetech
A11: Campo tensione ingresso | B11: 4–14 V | C11: Datasheet Feetech
A12: Corrente nominale | B12: 0,9 A | C12: Datasheet Feetech
A13: Corrente di stallo | B13: 2,7 A | C13: Datasheet Feetech
A14: Coppia nominale | B14: 10 kg·cm | C14: Datasheet Feetech
A15: Coppia di stallo | B15: 30 kg·cm | C15: Datasheet Feetech
A16: Velocità a vuoto | B16: 0,222 s / 60° (45 RPM) | C16: Datasheet Feetech
A17: Kt | B17: 11 kg·cm/A | C17: Datasheet Feetech
A18: Resistenza terminale motore | B18: 1,0 Ω | C18: Datasheet Feetech
A19: Corrente statica | B19: 30 mA | C19: Datasheet Feetech
A21: Specifiche meccaniche ufficiali
A22: Parametro | B22: Valore | C22: Origine | D22: Note
A23: Dimensioni | B23: 45,2 × 24,7 × 35 mm | C23: Datasheet Feetech
A24: Peso motore | B24: 55 ± 1 g | C24: Datasheet Feetech
A25: Gear ratio | B25: 1:345 | C25: Datasheet Feetech
A26: Case material | B26: PA+GF | C26: Datasheet Feetech
A27: Gear material | B27: Copper | C27: Datasheet Feetech
A28: Bearing | B28: Ball bearings | C28: Datasheet Feetech
A29: Angolo / encoder | B29: 360° / 12-bit magnetic encoder | C29: Datasheet Feetech
A30: Risoluzione | B30: 0,088°/pulse | C30: Datasheet Feetech
A31: Spline uscita | B31: 25T / OD 5,9 mm | C31: Datasheet Feetech
A33: Cavo / interfaccia
A34: Parametro | B34: Valore | C34: Origine | D34: Note
A35: Connettore | B35: 5264-3P | C35: Datasheet Feetech
A36: Pinout | B36: 1=GND, 2=Vcc, 3=Signal/TTL | C36: Datasheet Feetech
A37: Lunghezza cablaggio motore | B37: 15 cm | C37: Datasheet Feetech
A38: Sezione reale conduttore usata nel progetto | B38: 0,25 mm² (24 AWG) | C38: Da cavo selezionato dall’utente
A40: Batteria e condizioni di progetto
A41: Parametro | B41: Valore | C41: Origine | D41: Note
A42: Batteria | B42: LiPo 3S | C42: Progetto
A43: Tensione minima di riferimento | B43: 9,0 V | C43: Min safe tipico 3S | D43: Assunta come minima carica
A44: Tensione nominale | B44: 11,1 V | C44: 3S nominale
A45: Tensione massima | B45: 12,6 V | C45: 3S full charge
...

Sheet Power_Supply_Calc
A1: Analisi alimentazione – 12 servo su bus seriale con splitting power 3+3+3+3
A3: Input di progetto | E3: Topologia / assunzioni
A4: Tensione batteria minima | B4: 9 | C4: V | E4: • Bus dati TTL comune a 12 servo; 4 rami di alimentazione identici da 3 motori ciascuno.
A5: Tensione batteria nominale (3S) | B5: 11.1 | C5: V | E5: • Per ramo: PSU → servo1 → servo2 → servo3 con segmenti di 15 cm.
A6: Tensione batteria massima (3S full) | B6: 12.6 | C6: V | E6: • Caduta al 3° motore: ΔV_3 = Rseg·(I1+2·I2+3·I3); caso uniforme I1=I2=I3=I => ΔV_3 = 12·ρ·L·I/A.
A7: Resistività rame ρ | B7: 0.0175 | C7: Ω·mm²/m | E7: • Le stime di coppia/corrente fuori da 12 V sono derivate dai dati ufficiali a 12 V e dalla tensione effettiva sul motore.
A8: Lunghezza segmento cavo L | B8: 0.15 | C8: m
A9: Sezione conduttore A | B9: 0.25 | C9: mm²
A10: Motori per ramo | B10: 3 | C10: n
A11: Corrente nominale motore @12V | B11: 0.9 | C11: A
A12: Corrente stallo motore @12V | B12: 2.7 | C12: A
A13: Coppia nominale motore @12V | B13: 10 | C13: kg·cm
A14: Coppia stallo motore @12V | B14: 30 | C14: kg·cm
A15: Kt | B15: 11 | C15: kg·cm/A
A16: Interasse maggiore zampa | B16: 110 | C16: mm
A17: Peso cane robot | B17: 3.3 | C17: kg
A20: Parametri derivati
A21: Alpha ramo uniforme = 12·ρ·L/A | B21: =12*$B$7*$B$8/$B$9 -> 0.126 | C21: V/A
A22: k_I_nom = I_nom_12 / 12V | B22: =$B$11/12 -> 0.075 | C22: A/V
A23: k_I_max = I_stallo_12 / 12V | B23: =$B$12/12 -> 0.225 | C23: A/V
A26: Stati batteria: performance motore sul 3° servo del ramo (caso uniforme nel ramo)
A27: Stato batteria | B27: V batt [V] | C27: I nominale stim. [A] | D27: ΔV nominale [V] | E27: V ultimo nominale [V] | F27: T nominale stim. [kg·cm] | G27: I massima stim. [A] | H27: ΔV massima [V] | I27: V ultimo massima [V] | J27: T massima stim. [kg·cm]
A28: Minima carica | B28: =$B$4 -> 9 | C28: =($B$22*B28)/(1+$B$21*$B$22) -> 0.66868096 | D28: =$B$21*C28 -> 0.084253802 | E28: =B28-D28 -> 8.9157462 | F28: =$B$13*E28/12 -> 7.4297885 | G28: =($B$23*B28)/(1+$B$21*$B$23) -> 1.9691739 | H28: =$B$21*G28 -> 0.24811591 | I28: =B28-H28 -> 8.7518841 | J28: =$B$14*I28/12 -> 21.87971
A29: Nominale 3S | B29: =$B$5 -> 11.1 | C29: =($B$22*B29)/(1+$B$21*$B$22) -> 0.82470652 | D29: =$B$21*C29 -> 0.10391302 | E29: =B29-D29 -> 10.996087 | F29: =$B$13*E29/12 -> 9.1634058 | G29: =($B$23*B29)/(1+$B$21*$B$23) -> 2.4286478 | H29: =$B$21*G29 -> 0.30600963 | I29: =B29-H29 -> 10.79399 | J29: =$B$14*I29/12 -> 26.984976
A30: Massima carica | B30: =$B$6 -> 12.6 | C30: =($B$22*B30)/(1+$B$21*$B$22) -> 0.93615335 | D30: =$B$21*C30 -> 0.11795532 | E30: =B30-D30 -> 12.482045 | F30: =$B$13*E30/12 -> 10.401704 | G30: =($B$23*B30)/(1+$B$21*$B$23) -> 2.7568435 | H30: =$B$21*G30 -> 0.34736228 | I30: =B30-H30 -> 12.252638 | J30: =$B$14*I30/12 -> 30.631594
A32: Capacità Batteria (mAh) | B32: 9000
A33: Fattore capacità utile | B33: 0.8
A35: Correnti e potenze totali sistema (12 motori tutti uguali)
A36: Stato batteria | B36: I totale nominale [A] | C36: P totale nominale [W] | D36: I totale massima [A] | E36: P totale massima [W] | F36: Autonomia Stimata (min) | G36: Note
A37: =A28 -> Minima carica | B37: =12*C28 -> 8.0241716 | C37: =B37*B28 -> 72.217544 | D37: =12*G28 -> 23.630087 | E37: =D37*B28 -> 212.67078 | F37: =IFERROR((($B$32/1000)*$B$33)/B37,"")*60 -> 53.837333 | G37: Caso conservativo: tutti e 12 i motori allo stesso carico
A38: =A29 -> Nominale 3S | B38: =12*C29 -> 9.8964783 | C38: =B38*B29 -> 109.85091 | D38: =12*G29 -> 29.143774 | E38: =D38*B29 -> 323.49589 | F38: =IFERROR((($B$32/1000)*$B$33)/B38,"")*60 -> 43.651892 | G38: Caso conservativo: tutti e 12 i motori allo stesso carico
A39: =A30 -> Massima carica | B39: =12*C30 -> 11.23384 | C39: =B39*B30 -> 141.54639 | D39: =12*G30 -> 33.082122 | E39: =D39*B30 -> 416.83474 | F39: =IFERROR((($B$32/1000)*$B$33)/B39,"")*60 -> 38.455238 | G39: Caso conservativo: tutti e 12 i motori allo stesso carico
A41: Architettura servo / ID quadrupede 12 DOF
A42: Zampa | B42: Posizione | C42: Giunto | D42: ID Servo | E42: Nome consigliato | F42: Ramo power | G42: Ordine nel ramo
A43: Front Left | B43: Anteriore sinistra | C43: Shoulder | D43: 11 | E43: fl_shoulder | F43: Ramo 1 | G43: 1
A44: Front Left | B44: Anteriore sinistra | C44: Thigh | D44: 12 | E44: fl_thigh | F44: Ramo 1 | G44: 2
A45: Front Left | B45: Anteriore sinistra | C45: Calf | D45: 13 | E45: fl_calf | F45: Ramo 1 | G45: 3
A46: Front Right | B46: Anteriore destra | C46: Shoulder | D46: 21 | E46: fr_shoulder | F46: Ramo 2 | G46: 1
A47: Front Right | B47: Anteriore destra | C47: Thigh | D47: 22 | E47: fr_thigh | F47: Ramo 2 | G47: 2
A48: Front Right | B48: Anteriore destra | C48: Calf | D48: 23 | E48: fr_calf | F48: Ramo 2 | G48: 3
...

Sheet Robot_Load_Analysis
A1: Analisi carico robot – braccio critico 110 mm, massa totale 3,3 kg
A3: Input rilevanti (link ai dati del foglio Power_Supply_Calc)
A4: Massa robot [kg] | B4: =Power_Supply_Calc!$B$17 -> 3.3
A5: Braccio critico [mm] | B5: =Power_Supply_Calc!$B$16 -> 110
A6: Braccio critico [cm] | B6: =B5/10 -> 11
A7: Braccio critico [m] | B7: =B5/1000 -> 0.11
A8: Kt [kg·cm/A] | B8: =Power_Supply_Calc!$B$15 -> 11
A9: Alpha ramo uniforme [V/A] | B9: =Power_Supply_Calc!$B$21 -> 0.126
A10: Tensione batteria minima [V] | B10: =Power_Supply_Calc!$B$4 -> 9
A11: Tensione batteria nominale [V] | B11: =Power_Supply_Calc!$B$5 -> 11.1
A12: Tensione batteria massima [V] | B12: =Power_Supply_Calc!$B$6 -> 12.6
A15: Carico statico / quasi-statico del giunto più sollecitato
A16: Caso | B16: Zampe a terra | C16: Peso per zampa [kg] | D16: Forza per zampa [N] | E16: Coppia richiesta [kg·cm] | F16: Coppia richiesta [N·m] | G16: Corrente richiesta [A] | H16: Formula semplificata | I16: Note
A17: Camminata / sostegno 4 zampe | B17: 4 | C17: =$B$4/B17 -> 0.825 | D17: =C17*9.80665 -> 8.0904862 | E17: =C17*$B$6 -> 9.075 | F17: =E17*0.0980665 -> 0.88995349 | G17: =E17/$B$8 -> 0.825 | I17: Ipotesi statica, braccio massimo perpendicolare
A18: Caso gravoso / sostegno 2 zampe | B18: 2 | C18: =$B$4/B18 -> 1.65 | D18: =C18*9.80665 -> 16.180972 | E18: =C18*$B$6 -> 18.15 | F18: =E18*0.0980665 -> 1.779907 | G18: =E18/$B$8 -> 1.65 | I18: Ipotesi statica, braccio massimo perpendicolare
A21: Verifica coppia disponibile, corrente e caduta di tensione sul 3° motore del ramo
A22: Stato batteria | B22: Caso robot | C22: V batteria [V] | D22: T richiesta [kg·cm] | E22: I richiesta [A] | F22: ΔV ultimo motore [V] | G22: V ultimo motore [V] | H22: T max disponibile [kg·cm] | I22: I max stimata [A] | J22: Margine T_av/T_req | K22: Esito | L22: Ipotesi ramo
A23: Minima carica | B23: 4 zampe | C23: =$B$10 -> 9 | D23: =E17 -> 9.075 | E23: =G17 -> 0.825 | F23: =$B$9*E23 -> 0.10395 | G23: =C23-F23 -> 8.89605 | H23: =Power_Supply_Calc!$B$14*G23/12 -> 22.240125 | I23: =Power_Supply_Calc!$B$12*G23/12 -> 2.0016113 | J23: =H23/D23 -> 2.4507025 | K23: =IF(J23>=1,"OK","NO MARGIN") -> OK | L23: Conservativo: 3 motori del ramo allo stesso I del motore critico
A24: Minima carica | B24: 2 zampe | C24: =$B$10 -> 9 | D24: =E18 -> 18.15 | E24: =G18 -> 1.65 | F24: =$B$9*E24 -> 0.2079 | G24: =C24-F24 -> 8.7921 | H24: =Power_Supply_Calc!$B$14*G24/12 -> 21.98025 | I24: =Power_Supply_Calc!$B$12*G24/12 -> 1.9782225 | J24: =H24/D24 -> 1.2110331 | K24: =IF(J24>=1,"OK","NO MARGIN") -> OK | L24: Conservativo: 3 motori del ramo allo stesso I del motore critico
A25: Nominale 3S | B25: 4 zampe | C25: =$B$11 -> 11.1 | D25: =E17 -> 9.075 | E25: =G17 -> 0.825 | F25: =$B$9*E25 -> 0.10395 | G25: =C25-F25 -> 10.99605 | H25: =Power_Supply_Calc!$B$14*G25/12 -> 27.490125 | I25: =Power_Supply_Calc!$B$12*G25/12 -> 2.4741113 | J25: =H25/D25 -> 3.0292149 | K25: =IF(J25>=1,"OK","NO MARGIN") -> OK | L25: Conservativo: 3 motori del ramo allo stesso I del motore critico
A26: Nominale 3S | B26: 2 zampe | C26: =$B$11 -> 11.1 | D26: =E18 -> 18.15 | E26: =G18 -> 1.65 | F26: =$B$9*E26 -> 0.2079 | G26: =C26-F26 -> 10.8921 | H26: =Power_Supply_Calc!$B$14*G26/12 -> 27.23025 | I26: =Power_Supply_Calc!$B$12*G26/12 -> 2.4507225 | J26: =H26/D26 -> 1.5002893 | K26: =IF(J26>=1,"OK","NO MARGIN") -> OK | L26: Conservativo: 3 motori del ramo allo stesso I del motore critico
A27: Massima carica | B27: 4 zampe | C27: =$B$12 -> 12.6 | D27: =E17 -> 9.075 | E27: =G17 -> 0.825 | F27: =$B$9*E27 -> 0.10395 | G27: =C27-F27 -> 12.49605 | H27: =Power_Supply_Calc!$B$14*G27/12 -> 31.240125 | I27: =Power_Supply_Calc!$B$12*G27/12 -> 2.8116113 | J27: =H27/D27 -> 3.442438 | K27: =IF(J27>=1,"OK","NO MARGIN") -> OK | L27: Conservativo: 3 motori del ramo allo stesso I del motore critico
A28: Massima carica | B28: 2 zampe | C28: =$B$12 -> 12.6 | D28: =E18 -> 18.15 | E28: =G18 -> 1.65 | F28: =$B$9*E28 -> 0.2079 | G28: =C28-F28 -> 12.3921 | H28: =Power_Supply_Calc!$B$14*G28/12 -> 30.98025 | I28: =Power_Supply_Calc!$B$12*G28/12 -> 2.7882225 | J28: =H28/D28 -> 1.7069008 | K28: =IF(J28>=1,"OK","NO MARGIN") -> OK | L28: Conservativo: 3 motori del ramo allo stesso I del motore critico
A30: Sintesi tecnica
A31: Il caso peggiore è la verifica su 2 zampe. Se il margine è >1, la coppia massima stimata disponibile sul 3° motore del ramo supera la coppia richiesta dal giunto più sollecitato. La caduta di tensione è calcolata con la sezione reale 0,25 mm² (AWG24) e con lunghezza segmenti di 15 cm. La verifica è quasi-statica e non include accelerazioni, urti, inefficienze meccaniche, angoli sfavorevoli ulteriori o sovraccarichi dinamici.
