<?xml version='1.0' encoding='utf-8'?>
<!-- MATDOG MESH UNIT CONVENTION | STL vertex coordinates are exported from CAD in millimetres. Every visual and collision mesh applies scale="0.001 0.001 0.001" so the URDF remains SI-consistent: joint origins and CoM are metres; mass is kg; inertia is kg·m². -->
<robot name="matt_robodog_rev00">
  <!-- MATDOG DYNAMIC PROPERTIES REV00 | 17-link CAD baseline mass: 2.480 kg | Per-link standard URDF <inertial> blocks are populated from Solid Edge physical-property reports. CoM origins are expressed in each local link frame; inertia tensors are about those CoMs and expressed in link axes. Detailed provenance, symmetry derivation and aggregate validation are recorded in Coordinate_Cinematiche_matt_robodog_rev00.xlsx / Inertial_Properties. No standalone neck yaw actuator link is represented in REV00. -->
  <link name="base_link">
    <!-- MATDOG_DYNAMIC_PROPERTIES | mass_kg=1.282000 | coM_frame=local_link | tensor_frame=local_link_at_com | method=CAD direct: principal axes + radii of gyration | symmetry=direct CAD export | source=physprop__base_link.txt + weight_breakdown_summary.txt -->
    <inertial>
      <origin xyz="0.00584 -0.00065 0.02773" rpy="0 0 0" />
      <mass value="1.282000" />
      <inertia ixx="0.00147265728657" ixy="1.42294028465e-05" ixz="-0.000443609672652" iyy="0.00887012995059" iyz="-7.70141299896e-06" izz="0.00949906085204" />
    </inertial>
    <visual>
      <origin xyz="0 0 0" rpy="0 0 0" />
      <geometry>
        <mesh filename="meshes/base_link.stl"  scale="0.001 0.001 0.001" />
      </geometry>
      <material name="base_link_mat">
        <color rgba="0.10 0.10 0.10 1.0" />
      </material>
    </visual>
    <collision>
      <origin xyz="0 0 0" rpy="0 0 0" />
      <geometry>
        <mesh filename="meshes/base_link.stl"  scale="0.001 0.001 0.001" />
      </geometry>
    </collision>
  </link>
  <link name="lf_hip_link">
    <!-- MATDOG_DYNAMIC_PROPERTIES | mass_kg=0.050000 | coM_frame=local_link | tensor_frame=local_link_at_com | method=CAD direct: principal axes + radii of gyration | symmetry=direct CAD export | source=physprop__lf_hip_link.txt + weight_breakdown_summary.txt -->
    <inertial>
      <origin xyz="0.00366 0.02982 0.00694" rpy="0 0 0" />
      <mass value="0.050000" />
      <inertia ixx="4.02252347591e-05" ixy="-1.31462768927e-06" ixz="-1.13953716339e-06" iyy="1.8958128496e-05" iyz="-4.46400670021e-06" izz="4.54280867449e-05" />
    </inertial>
    <visual>
      <origin xyz="0 0 0" rpy="0 0 0" />
      <geometry>
        <mesh filename="meshes/lf_hip_link.stl"  scale="0.001 0.001 0.001" />
      </geometry>
      <material name="lf_hip_link_mat">
        <color rgba="0.10 0.10 0.10 1.0" />
      </material>
    </visual>
    <collision>
      <origin xyz="0 0 0" rpy="0 0 0" />
      <geometry>
        <mesh filename="meshes/lf_hip_link.stl"  scale="0.001 0.001 0.001" />
      </geometry>
    </collision>
  </link>
  <link name="lf_upper_leg_link">
    <!-- MATDOG_DYNAMIC_PROPERTIES | mass_kg=0.172500 | coM_frame=local_link | tensor_frame=local_link_at_com | method=CAD direct: principal axes + radii of gyration | symmetry=direct CAD export | source=physprop__lf_upper_leg_link.txt + weight_breakdown_summary.txt -->
    <inertial>
      <origin xyz="0.00108 0.00015 -0.04503" rpy="0 0 0" />
      <mass value="0.172500" />
      <inertia ixx="0.000205436660094" ixy="-5.63507198417e-08" ixz="0" iyy="0.000199175976156" iyz="0" izz="3.111294525e-05" />
    </inertial>
    <visual>
      <origin xyz="0 0 0" rpy="0 0 0" />
      <geometry>
        <mesh filename="meshes/lf_upper_leg_link.stl"  scale="0.001 0.001 0.001" />
      </geometry>
      <material name="lf_upper_leg_link_mat">
        <color rgba="0.10 0.10 0.10 1.0" />
      </material>
    </visual>
    <collision>
      <origin xyz="0 0 0" rpy="0 0 0" />
      <geometry>
        <mesh filename="meshes/lf_upper_leg_link.stl"  scale="0.001 0.001 0.001" />
      </geometry>
    </collision>
  </link>
  <link name="lf_lower_leg_link">
    <!-- MATDOG_DYNAMIC_PROPERTIES | mass_kg=0.059500 | coM_frame=local_link | tensor_frame=local_link_at_com | method=CAD direct: principal axes + radii of gyration | symmetry=direct CAD export | source=physprop__lf_lower_leg_link.txt + weight_breakdown_summary.txt -->
    <inertial>
      <origin xyz="0.03075 -0.00118 -0.01958" rpy="0 0 0" />
      <mass value="0.059500" />
      <inertia ixx="2.15172642767e-05" ixy="6.0930015348e-07" ixz="1.68302311374e-05" iyy="0.000102530052784" iyz="-3.71953235117e-07" izz="0.000104321477439" />
    </inertial>
    <visual>
      <origin xyz="0 0 0" rpy="0 0 0" />
      <geometry>
        <mesh filename="meshes/lf_lower_leg_link.stl"  scale="0.001 0.001 0.001" />
      </geometry>
      <material name="lf_lower_leg_link_mat">
        <color rgba="0.10 0.10 0.10 1.0" />
      </material>
    </visual>
    <collision>
      <origin xyz="0 0 0" rpy="0 0 0" />
      <geometry>
        <mesh filename="meshes/lf_lower_leg_link.stl"  scale="0.001 0.001 0.001" />
      </geometry>
    </collision>
  </link>
  <link name="lf_foot_link">
    <!-- MATDOG_DYNAMIC_PROPERTIES | mass_kg=0.017500 | coM_frame=local_link | tensor_frame=local_link_at_com | method=CAD direct: principal axes + radii of gyration | symmetry=direct CAD export | source=physprop__lf_foot_link.txt + weight_breakdown_summary.txt -->
    <inertial>
      <origin xyz="-0.00052 0 0.01548" rpy="0 0 0" />
      <mass value="0.017500" />
      <inertia ixx="1.14526961866e-06" ixy="0" ixz="-1.55064671079e-08" iyy="1.20267175e-06" iyz="0" izz="1.14835213134e-06" />
    </inertial>
    <visual>
      <origin xyz="0 0 0" rpy="0 0 0" />
      <geometry>
        <mesh filename="meshes/lf_foot_link.stl"  scale="0.001 0.001 0.001" />
      </geometry>
      <material name="lf_foot_link_mat">
        <color rgba="0.10 0.10 0.10 1.0" />
      </material>
    </visual>
    <collision>
      <origin xyz="0 0 0" rpy="0 0 0" />
      <geometry>
        <mesh filename="meshes/lf_foot_link.stl"  scale="0.001 0.001 0.001" />
      </geometry>
    </collision>
  </link>
  <link name="rf_hip_link">
    <!-- MATDOG_DYNAMIC_PROPERTIES | mass_kg=0.050000 | coM_frame=local_link | tensor_frame=local_link_at_com | method=CAD symmetry-derived from LF: local Y reflection | symmetry=Y mirror of LF hip | source=physprop__lf_hip_link.txt + weight_breakdown_summary.txt -->
    <inertial>
      <origin xyz="0.00366 -0.02982 0.00694" rpy="0 0 0" />
      <mass value="0.050000" />
      <inertia ixx="4.02252347591e-05" ixy="1.31462768927e-06" ixz="-1.13953716339e-06" iyy="1.8958128496e-05" iyz="4.46400670021e-06" izz="4.54280867449e-05" />
    </inertial>
    <visual>
      <origin xyz="0 0 0" rpy="0 0 0" />
      <geometry>
        <mesh filename="meshes/rf_hip_link.stl"  scale="0.001 0.001 0.001" />
      </geometry>
      <material name="rf_hip_link_mat">
        <color rgba="0.10 0.10 0.10 1.0" />
      </material>
    </visual>
    <collision>
      <origin xyz="0 0 0" rpy="0 0 0" />
      <geometry>
        <mesh filename="meshes/rf_hip_link.stl"  scale="0.001 0.001 0.001" />
      </geometry>
    </collision>
  </link>
  <link name="rf_upper_leg_link">
    <!-- MATDOG_DYNAMIC_PROPERTIES | mass_kg=0.172500 | coM_frame=local_link | tensor_frame=local_link_at_com | method=CAD symmetry-derived from LF: local Y reflection | symmetry=Y mirror of LF upper | source=physprop__lf_upper_leg_link.txt + weight_breakdown_summary.txt -->
    <inertial>
      <origin xyz="0.00108 -0.00015 -0.04503" rpy="0 0 0" />
      <mass value="0.172500" />
      <inertia ixx="0.000205436660094" ixy="5.63507198417e-08" ixz="0" iyy="0.000199175976156" iyz="0" izz="3.111294525e-05" />
    </inertial>
    <visual>
      <origin xyz="0 0 0" rpy="0 0 0" />
      <geometry>
        <mesh filename="meshes/rf_upper_leg_link.stl"  scale="0.001 0.001 0.001" />
      </geometry>
      <material name="rf_upper_leg_link_mat">
        <color rgba="0.10 0.10 0.10 1.0" />
      </material>
    </visual>
    <collision>
      <origin xyz="0 0 0" rpy="0 0 0" />
      <geometry>
        <mesh filename="meshes/rf_upper_leg_link.stl"  scale="0.001 0.001 0.001" />
      </geometry>
    </collision>
  </link>
  <link name="rf_lower_leg_link">
    <!-- MATDOG_DYNAMIC_PROPERTIES | mass_kg=0.059500 | coM_frame=local_link | tensor_frame=local_link_at_com | method=CAD symmetry-derived from LF: local Y reflection | symmetry=Y mirror of LF lower | source=physprop__lf_lower_leg_link.txt + weight_breakdown_summary.txt -->
    <inertial>
      <origin xyz="0.03075 0.00118 -0.01958" rpy="0 0 0" />
      <mass value="0.059500" />
      <inertia ixx="2.15172642767e-05" ixy="-6.0930015348e-07" ixz="1.68302311374e-05" iyy="0.000102530052784" iyz="3.71953235117e-07" izz="0.000104321477439" />
    </inertial>
    <visual>
      <origin xyz="0 0 0" rpy="0 0 0" />
      <geometry>
        <mesh filename="meshes/rf_lower_leg_link.stl"  scale="0.001 0.001 0.001" />
      </geometry>
      <material name="rf_lower_leg_link_mat">
        <color rgba="0.10 0.10 0.10 1.0" />
      </material>
    </visual>
    <collision>
      <origin xyz="0 0 0" rpy="0 0 0" />
      <geometry>
        <mesh filename="meshes/rf_lower_leg_link.stl"  scale="0.001 0.001 0.001" />
      </geometry>
    </collision>
  </link>
  <link name="rf_foot_link">
    <!-- MATDOG_DYNAMIC_PROPERTIES | mass_kg=0.017500 | coM_frame=local_link | tensor_frame=local_link_at_com | method=CAD symmetry-derived from LF: identical foot geometry | symmetry=identical foot geometry; LF local inertia copied | source=physprop__lf_foot_link.txt + weight_breakdown_summary.txt -->
    <inertial>
      <origin xyz="-0.00052 0 0.01548" rpy="0 0 0" />
      <mass value="0.017500" />
      <inertia ixx="1.14526961866e-06" ixy="0" ixz="-1.55064671079e-08" iyy="1.20267175e-06" iyz="0" izz="1.14835213134e-06" />
    </inertial>
    <visual>
      <origin xyz="0 0 0" rpy="0 0 0" />
      <geometry>
        <mesh filename="meshes/rf_foot_link.stl"  scale="0.001 0.001 0.001" />
      </geometry>
      <material name="rf_foot_link_mat">
        <color rgba="0.10 0.10 0.10 1.0" />
      </material>
    </visual>
    <collision>
      <origin xyz="0 0 0" rpy="0 0 0" />
      <geometry>
        <mesh filename="meshes/rf_foot_link.stl"  scale="0.001 0.001 0.001" />
      </geometry>
    </collision>
  </link>
  <link name="rh_hip_link">
    <!-- MATDOG_DYNAMIC_PROPERTIES | mass_kg=0.050000 | coM_frame=local_link | tensor_frame=local_link_at_com | method=CAD symmetry-derived from LF: local Y reflection | symmetry=Y mirror of LF hip | source=physprop__lf_hip_link.txt + weight_breakdown_summary.txt -->
    <inertial>
      <origin xyz="0.00366 -0.02982 0.00694" rpy="0 0 0" />
      <mass value="0.050000" />
      <inertia ixx="4.02252347591e-05" ixy="1.31462768927e-06" ixz="-1.13953716339e-06" iyy="1.8958128496e-05" iyz="4.46400670021e-06" izz="4.54280867449e-05" />
    </inertial>
    <visual>
      <origin xyz="0 0 0" rpy="0 0 0" />
      <geometry>
        <mesh filename="meshes/rh_hip_link.stl"  scale="0.001 0.001 0.001" />
      </geometry>
      <material name="rh_hip_link_mat">
        <color rgba="0.10 0.10 0.10 1.0" />
      </material>
    </visual>
    <collision>
      <origin xyz="0 0 0" rpy="0 0 0" />
      <geometry>
        <mesh filename="meshes/rh_hip_link.stl"  scale="0.001 0.001 0.001" />
      </geometry>
    </collision>
  </link>
  <link name="rh_upper_leg_link">
    <!-- MATDOG_DYNAMIC_PROPERTIES | mass_kg=0.172500 | coM_frame=local_link | tensor_frame=local_link_at_com | method=CAD symmetry-derived from LF: local Y reflection | symmetry=Y mirror of LF upper | source=physprop__lf_upper_leg_link.txt + weight_breakdown_summary.txt -->
    <inertial>
      <origin xyz="0.00108 -0.00015 -0.04503" rpy="0 0 0" />
      <mass value="0.172500" />
      <inertia ixx="0.000205436660094" ixy="5.63507198417e-08" ixz="0" iyy="0.000199175976156" iyz="0" izz="3.111294525e-05" />
    </inertial>
    <visual>
      <origin xyz="0 0 0" rpy="0 0 0" />
      <geometry>
        <mesh filename="meshes/rh_upper_leg_link.stl"  scale="0.001 0.001 0.001" />
      </geometry>
      <material name="rh_upper_leg_link_mat">
        <color rgba="0.10 0.10 0.10 1.0" />
      </material>
    </visual>
    <collision>
      <origin xyz="0 0 0" rpy="0 0 0" />
      <geometry>
        <mesh filename="meshes/rh_upper_leg_link.stl"  scale="0.001 0.001 0.001" />
      </geometry>
    </collision>
  </link>
  <link name="rh_lower_leg_link">
    <!-- MATDOG_DYNAMIC_PROPERTIES | mass_kg=0.059500 | coM_frame=local_link | tensor_frame=local_link_at_com | method=CAD symmetry-derived from LF: local Y reflection | symmetry=Y mirror of LF lower | source=physprop__lf_lower_leg_link.txt + weight_breakdown_summary.txt -->
    <inertial>
      <origin xyz="0.03075 0.00118 -0.01958" rpy="0 0 0" />
      <mass value="0.059500" />
      <inertia ixx="2.15172642767e-05" ixy="-6.0930015348e-07" ixz="1.68302311374e-05" iyy="0.000102530052784" iyz="3.71953235117e-07" izz="0.000104321477439" />
    </inertial>
    <visual>
      <origin xyz="0 0 0" rpy="0 0 0" />
      <geometry>
        <mesh filename="meshes/rh_lower_leg_link.stl"  scale="0.001 0.001 0.001" />
      </geometry>
      <material name="rh_lower_leg_link_mat">
        <color rgba="0.10 0.10 0.10 1.0" />
      </material>
    </visual>
    <collision>
      <origin xyz="0 0 0" rpy="0 0 0" />
      <geometry>
        <mesh filename="meshes/rh_lower_leg_link.stl"  scale="0.001 0.001 0.001" />
      </geometry>
    </collision>
  </link>
  <link name="rh_foot_link">
    <!-- MATDOG_DYNAMIC_PROPERTIES | mass_kg=0.017500 | coM_frame=local_link | tensor_frame=local_link_at_com | method=CAD symmetry-derived from LF: identical foot geometry | symmetry=identical foot geometry; LF local inertia copied | source=physprop__lf_foot_link.txt + weight_breakdown_summary.txt -->
    <inertial>
      <origin xyz="-0.00052 0 0.01548" rpy="0 0 0" />
      <mass value="0.017500" />
      <inertia ixx="1.14526961866e-06" ixy="0" ixz="-1.55064671079e-08" iyy="1.20267175e-06" iyz="0" izz="1.14835213134e-06" />
    </inertial>
    <visual>
      <origin xyz="0 0 0" rpy="0 0 0" />
      <geometry>
        <mesh filename="meshes/rh_foot_link.stl"  scale="0.001 0.001 0.001" />
      </geometry>
      <material name="rh_foot_link_mat">
        <color rgba="0.10 0.10 0.10 1.0" />
      </material>
    </visual>
    <collision>
      <origin xyz="0 0 0" rpy="0 0 0" />
      <geometry>
        <mesh filename="meshes/rh_foot_link.stl"  scale="0.001 0.001 0.001" />
      </geometry>
    </collision>
  </link>
  <link name="lh_hip_link">
    <!-- MATDOG_DYNAMIC_PROPERTIES | mass_kg=0.050000 | coM_frame=local_link | tensor_frame=local_link_at_com | method=CAD symmetry-derived from LF: same left-side local geometry | symmetry=same left-side local frame as LF | source=physprop__lf_hip_link.txt + weight_breakdown_summary.txt -->
    <inertial>
      <origin xyz="0.00366 0.02982 0.00694" rpy="0 0 0" />
      <mass value="0.050000" />
      <inertia ixx="4.02252347591e-05" ixy="-1.31462768927e-06" ixz="-1.13953716339e-06" iyy="1.8958128496e-05" iyz="-4.46400670021e-06" izz="4.54280867449e-05" />
    </inertial>
    <visual>
      <origin xyz="0 0 0" rpy="0 0 0" />
      <geometry>
        <mesh filename="meshes/lh_hip_link.stl"  scale="0.001 0.001 0.001" />
      </geometry>
      <material name="lh_hip_link_mat">
        <color rgba="0.10 0.10 0.10 1.0" />
      </material>
    </visual>
    <collision>
      <origin xyz="0 0 0" rpy="0 0 0" />
      <geometry>
        <mesh filename="meshes/lh_hip_link.stl"  scale="0.001 0.001 0.001" />
      </geometry>
    </collision>
  </link>
  <link name="lh_upper_leg_link">
    <!-- MATDOG_DYNAMIC_PROPERTIES | mass_kg=0.172500 | coM_frame=local_link | tensor_frame=local_link_at_com | method=CAD symmetry-derived from LF: same left-side local geometry | symmetry=same left-side local frame as LF | source=physprop__lf_upper_leg_link.txt + weight_breakdown_summary.txt -->
    <inertial>
      <origin xyz="0.00108 0.00015 -0.04503" rpy="0 0 0" />
      <mass value="0.172500" />
      <inertia ixx="0.000205436660094" ixy="-5.63507198417e-08" ixz="0" iyy="0.000199175976156" iyz="0" izz="3.111294525e-05" />
    </inertial>
    <visual>
      <origin xyz="0 0 0" rpy="0 0 0" />
      <geometry>
        <mesh filename="meshes/lh_upper_leg_link.stl"  scale="0.001 0.001 0.001" />
      </geometry>
      <material name="lh_upper_leg_link_mat">
        <color rgba="0.10 0.10 0.10 1.0" />
      </material>
    </visual>
    <collision>
      <origin xyz="0 0 0" rpy="0 0 0" />
      <geometry>
        <mesh filename="meshes/lh_upper_leg_link.stl"  scale="0.001 0.001 0.001" />
      </geometry>
    </collision>
  </link>
  <link name="lh_lower_leg_link">
    <!-- MATDOG_DYNAMIC_PROPERTIES | mass_kg=0.059500 | coM_frame=local_link | tensor_frame=local_link_at_com | method=CAD symmetry-derived from LF: same left-side local geometry | symmetry=same left-side local frame as LF | source=physprop__lf_lower_leg_link.txt + weight_breakdown_summary.txt -->
    <inertial>
      <origin xyz="0.03075 -0.00118 -0.01958" rpy="0 0 0" />
      <mass value="0.059500" />
      <inertia ixx="2.15172642767e-05" ixy="6.0930015348e-07" ixz="1.68302311374e-05" iyy="0.000102530052784" iyz="-3.71953235117e-07" izz="0.000104321477439" />
    </inertial>
    <visual>
      <origin xyz="0 0 0" rpy="0 0 0" />
      <geometry>
        <mesh filename="meshes/lh_lower_leg_link.stl"  scale="0.001 0.001 0.001" />
      </geometry>
      <material name="lh_lower_leg_link_mat">
        <color rgba="0.10 0.10 0.10 1.0" />
      </material>
    </visual>
    <collision>
      <origin xyz="0 0 0" rpy="0 0 0" />
      <geometry>
        <mesh filename="meshes/lh_lower_leg_link.stl"  scale="0.001 0.001 0.001" />
      </geometry>
    </collision>
  </link>
  <link name="lh_foot_link">
    <!-- MATDOG_DYNAMIC_PROPERTIES | mass_kg=0.017500 | coM_frame=local_link | tensor_frame=local_link_at_com | method=CAD symmetry-derived from LF: identical foot geometry | symmetry=identical foot geometry; LF local inertia copied | source=physprop__lf_foot_link.txt + weight_breakdown_summary.txt -->
    <inertial>
      <origin xyz="-0.00052 0 0.01548" rpy="0 0 0" />
      <mass value="0.017500" />
      <inertia ixx="1.14526961866e-06" ixy="0" ixz="-1.55064671079e-08" iyy="1.20267175e-06" iyz="0" izz="1.14835213134e-06" />
    </inertial>
    <visual>
      <origin xyz="0 0 0" rpy="0 0 0" />
      <geometry>
        <mesh filename="meshes/lh_foot_link.stl"  scale="0.001 0.001 0.001" />
      </geometry>
      <material name="lh_foot_link_mat">
        <color rgba="0.10 0.10 0.10 1.0" />
      </material>
    </visual>
    <collision>
      <origin xyz="0 0 0" rpy="0 0 0" />
      <geometry>
        <mesh filename="meshes/lh_foot_link.stl"  scale="0.001 0.001 0.001" />
      </geometry>
    </collision>
  </link>
  <joint name="lf_hip_joint" type="revolute">
    <parent link="base_link" />
    <child link="lf_hip_link" />
    <origin xyz="0.1125 0.0475 0.0465" rpy="0 0 0" />
    <axis xyz="1 0 0" />
    <limit lower="-0.785398163397" upper="0.785398163397" effort="0.902244" velocity="3.03687289847" />
    <dynamics damping="0" friction="0" />
    <hardware>
      <motorType>Feetech ST3215</motorType>
      <motorId>13</motorId>
      <motorDirection>1</motorDirection>
      <armature>0</armature>
    </hardware>
  </joint>
  <joint name="lf_upper_leg_joint" type="revolute">
    <parent link="lf_hip_link" />
    <child link="lf_upper_leg_link" />
    <origin xyz="0 0.048 0" rpy="0 0 0" />
    <axis xyz="0 1 0" />
    <limit lower="-0.916297857297" upper="2.138028333693" effort="0.902244" velocity="3.03687289847" />
    <dynamics damping="0" friction="0" />
    <hardware>
      <motorType>Feetech ST3215</motorType>
      <motorId>12</motorId>
      <motorDirection>1</motorDirection>
      <armature>0</armature>
    </hardware>
  </joint>
  <joint name="lf_lower_leg_joint" type="revolute">
    <parent link="lf_upper_leg_link" />
    <child link="lf_lower_leg_link" />
    <origin xyz="0 0 -0.09" rpy="0 0 0" />
    <axis xyz="0 1 0" />
    <limit lower="-1.605702911835" upper="0.654498469498" effort="0.902244" velocity="3.03687289847" />
    <dynamics damping="0" friction="0" />
    <hardware>
      <motorType>Feetech ST3215</motorType>
      <motorId>11</motorId>
      <motorDirection>1</motorDirection>
      <armature>0</armature>
    </hardware>
  </joint>
  <joint name="lf_foot_joint" type="fixed">
    <parent link="lf_lower_leg_link" />
    <child link="lf_foot_link" />
    <origin xyz="0.107 -0.0015 -0.0499" rpy="0 0 0" />
  </joint>
  <joint name="rf_hip_joint" type="revolute">
    <parent link="base_link" />
    <child link="rf_hip_link" />
    <origin xyz="0.1125 -0.0475 0.0465" rpy="0 0 0" />
    <axis xyz="1 0 0" />
    <limit lower="-0.785398163397" upper="0.785398163397" effort="0.902244" velocity="3.03687289847" />
    <dynamics damping="0" friction="0" />
    <hardware>
      <motorType>Feetech ST3215</motorType>
      <motorId>23</motorId>
      <motorDirection>1</motorDirection>
      <armature>0</armature>
    </hardware>
  </joint>
  <joint name="rf_upper_leg_joint" type="revolute">
    <parent link="rf_hip_link" />
    <child link="rf_upper_leg_link" />
    <origin xyz="0 -0.048 0" rpy="0 0 0" />
    <axis xyz="0 1 0" />
    <limit lower="-0.916297857297" upper="2.138028333693" effort="0.902244" velocity="3.03687289847" />
    <dynamics damping="0" friction="0" />
    <hardware>
      <motorType>Feetech ST3215</motorType>
      <motorId>22</motorId>
      <motorDirection>-1</motorDirection>
      <armature>0</armature>
    </hardware>
  </joint>
  <joint name="rf_lower_leg_joint" type="revolute">
    <parent link="rf_upper_leg_link" />
    <child link="rf_lower_leg_link" />
    <origin xyz="0 0 -0.09" rpy="0 0 0" />
    <axis xyz="0 1 0" />
    <limit lower="-1.605702911835" upper="0.654498469498" effort="0.902244" velocity="3.03687289847" />
    <dynamics damping="0" friction="0" />
    <hardware>
      <motorType>Feetech ST3215</motorType>
      <motorId>21</motorId>
      <motorDirection>-1</motorDirection>
      <armature>0</armature>
    </hardware>
  </joint>
  <joint name="rf_foot_joint" type="fixed">
    <parent link="rf_lower_leg_link" />
    <child link="rf_foot_link" />
    <origin xyz="0.107 0.0015 -0.0499" rpy="0 0 0" />
  </joint>
  <joint name="rh_hip_joint" type="revolute">
    <parent link="base_link" />
    <child link="rh_hip_link" />
    <origin xyz="-0.1125 -0.0475 0.0265" rpy="0 0 0" />
    <axis xyz="1 0 0" />
    <limit lower="-0.785398163397" upper="0.785398163397" effort="0.902244" velocity="3.03687289847" />
    <dynamics damping="0" friction="0" />
    <hardware>
      <motorType>Feetech ST3215</motorType>
      <motorId>33</motorId>
      <motorDirection>-1</motorDirection>
      <armature>0</armature>
    </hardware>
  </joint>
  <joint name="rh_upper_leg_joint" type="revolute">
    <parent link="rh_hip_link" />
    <child link="rh_upper_leg_link" />
    <origin xyz="0 -0.048 0" rpy="0 0 0" />
    <axis xyz="0 1 0" />
    <limit lower="-0.916297857297" upper="2.138028333693" effort="0.902244" velocity="3.03687289847" />
    <dynamics damping="0" friction="0" />
    <hardware>
      <motorType>Feetech ST3215</motorType>
      <motorId>32</motorId>
      <motorDirection>-1</motorDirection>
      <armature>0</armature>
    </hardware>
  </joint>
  <joint name="rh_lower_leg_joint" type="revolute">
    <parent link="rh_upper_leg_link" />
    <child link="rh_lower_leg_link" />
    <origin xyz="0 0 -0.09" rpy="0 0 0" />
    <axis xyz="0 1 0" />
    <limit lower="-1.605702911835" upper="0.654498469498" effort="0.902244" velocity="3.03687289847" />
    <dynamics damping="0" friction="0" />
    <hardware>
      <motorType>Feetech ST3215</motorType>
      <motorId>31</motorId>
      <motorDirection>-1</motorDirection>
      <armature>0</armature>
    </hardware>
  </joint>
  <joint name="rh_foot_joint" type="fixed">
    <parent link="rh_lower_leg_link" />
    <child link="rh_foot_link" />
    <origin xyz="0.107 0.0015 -0.0499" rpy="0 0 0" />
  </joint>
  <joint name="lh_hip_joint" type="revolute">
    <parent link="base_link" />
    <child link="lh_hip_link" />
    <origin xyz="-0.1125 0.0475 0.0265" rpy="0 0 0" />
    <axis xyz="1 0 0" />
    <limit lower="-0.785398163397" upper="0.785398163397" effort="0.902244" velocity="3.03687289847" />
    <dynamics damping="0" friction="0" />
    <hardware>
      <motorType>Feetech ST3215</motorType>
      <motorId>43</motorId>
      <motorDirection>-1</motorDirection>
      <armature>0</armature>
    </hardware>
  </joint>
  <joint name="lh_upper_leg_joint" type="revolute">
    <parent link="lh_hip_link" />
    <child link="lh_upper_leg_link" />
    <origin xyz="0 0.048 0" rpy="0 0 0" />
    <axis xyz="0 1 0" />
    <limit lower="-0.916297857297" upper="2.138028333693" effort="0.902244" velocity="3.03687289847" />
    <dynamics damping="0" friction="0" />
    <hardware>
      <motorType>Feetech ST3215</motorType>
      <motorId>42</motorId>
      <motorDirection>1</motorDirection>
      <armature>0</armature>
    </hardware>
  </joint>
  <joint name="lh_lower_leg_joint" type="revolute">
    <parent link="lh_upper_leg_link" />
    <child link="lh_lower_leg_link" />
    <origin xyz="0 0 -0.09" rpy="0 0 0" />
    <axis xyz="0 1 0" />
    <limit lower="-1.605702911835" upper="0.654498469498" effort="0.902244" velocity="3.03687289847" />
    <dynamics damping="0" friction="0" />
    <hardware>
      <motorType>Feetech ST3215</motorType>
      <motorId>41</motorId>
      <motorDirection>1</motorDirection>
      <armature>0</armature>
    </hardware>
  </joint>
  <joint name="lh_foot_joint" type="fixed">
    <parent link="lh_lower_leg_link" />
    <child link="lh_foot_link" />
    <origin xyz="0.107 -0.0015 -0.0499" rpy="0 0 0" />
  </joint>
</robot>